Workbook

Sheet Dados Programa
B1: Programação Perfiladeira U 4,75 MM - 2026 | J1: 900
I2: =SUM(I4:I42) -> 902 | J2: =SUM(J4:J53) -> 397.071 | O2: =SUM(O4:O61) -> 164.5371
A3: OP | B3: Cód. | C3: Descrição do Produto | D3: Esp. | E3: Kg/m | F3: Ton/H | G3: Veloc. Programado | H3: Tempo Programado | I3: Programado | J3: Realizado | K3: Inicio | L3: Termino | M3: Data prevista Comercial | N3: Matéria Prima | O3: Pedido de Venda | P3: Observação
B4: PRF10255 | C4: PERFIL U ENRIJ LQ 3,00 X 200 X 75 X 20 MM | D4: 3 | I4: 10 | J4: 12.07 | K4: 46174 | L4: 46174 | M4: =L4+4 -> 46178 | N4: mp-ok | O4: =-1*(IF(VLOOKUP(B4,Estoque!B:J,8,FALSE)>0,0,VLOOKUP(B4,Estoque!B:J,8))) -> 0 | P4: 0022.36086
B5: PRF10246 | C5: PERFIL U ENRIJ LQ 3,35 X 200 X 75 X 20 MM | D5: 3.35 | I5: 10 | J5: 8.483 | K5: 46175 | L5: 46175 | M5: =L5+4 -> 46179 | N5: mp-ok | O5: 5.236 | P5: 0022.36242
B6: PRF10120 | C6: PERFIL U ENRIJ LQ 2,25 X 200 X 75 X 20 MM | D6: 2.25 | I6: 20 | J6: 6.004 | K6: - | L6: - | M6: =L6+4 -> #VALUE! | N6: 6t-ok (SEM MP) | O6: =-1*(IF(VLOOKUP(B6,Estoque!B:J,8,FALSE)>0,0,VLOOKUP(B6,Estoque!B:J,8))) -> 0 | P6: 0022.36100
B7: PRF10060 | C7: PERFIL U ENRIJ LQ 2,00 X 200 X 75 X 20 MM | D7: 2 | I7: 35 | J7: 34.365 | K7: 46176 | L7: 46176 | M7: =L7+2 -> 46178 | N7: 31t-ok | O7: =-1*(IF(VLOOKUP(B7,Estoque!B:J,8,FALSE)>0,0,VLOOKUP(B7,Estoque!B:J,8))) -> 0 | P7: 0022.36101
B8: PRF10180 | C8: PERFIL U ENRIJ LQ 2,65 X 200 X 75 X 20 MM | D8: 2.65 | I8: 25 | J8: 22.46 | K8: 46178 | L8: 46178 | M8: =L8+3 -> 46181 | N8: mp-ok | O8: =-1*(IF(VLOOKUP(B8,Estoque!B:J,8,FALSE)>0,0,VLOOKUP(B8,Estoque!B:J,8))) -> 0.67 | P8: 0022.36103
B9: PRF10370 | C9: PERFIL U SIMPLES LQ 2,00 X 200 X 50 MM | D9: 2 | I9: 10 | J9: 11.56 | K9: 46181 | L9: 46181 | M9: =L9+2 -> 46183 | N9: mp-ok | O9: =-1*(IF(VLOOKUP(B9,Estoque!B:J,8,FALSE)>0,0,VLOOKUP(B9,Estoque!B:J,8))) -> 0 | P9: 0022.36104
B10: PRF10550 | C10: PERFIL U SIMPLES LQ 2,65 X 200 X 50 MM | D10: 2.65 | I10: 15 | J10: 24.13 | K10: 46181 | L10: 46181 | M10: =L10+2 -> 46183 | N10: mp-ok | O10: =-1*(IF(VLOOKUP(B10,Estoque!B:J,8,FALSE)>0,0,VLOOKUP(B10,Estoque!B:J,8))) -> 0 | P10: 0022.36105
B11: PRF10642 | C11: PERFIL U SIMPLES LQ 3,00 X 200 X 50 MM | D11: 3 | I11: 30 | J11: 38.03 | K11: 46181 | L11: 46181 | M11: =L11+3 -> 46184 | N11: mp-ok | O11: =-1*(IF(VLOOKUP(B11,Estoque!B:J,8,FALSE)>0,0,VLOOKUP(B11,Estoque!B:J,8))) -> 0 | P11: 0022.36106
B12: PRF100081 | C12: PERFIL U ENRIJ LQ 1,80 X 150 X 60 X 20 MM - COMPR. ESPECIAL | D12: 1.8 | I12: 16 | J12: 14.4596 | K12: 46182 | L12: 46182 | M12: =L12+2 -> 46184 | N12: mp-ok | O12: 14.4596 | P12: 0022.36230 | Q12: COMPRIMENTO ESPECIAL
B13: PRF10008 | C13: PERFIL U ENRIJ LQ 1,80 X 150 X 60 X 20 MM | D13: 1.8 | J13: 3.4954 | K13: - | L13: - | M13: - | N13: passou porque tinha no chão | O13: 0 | P13: 0022.36230
B14: PRZ101401 | C14: PERFIL U ENRIJ ZC 1,95 X 150 X 60 X 20 MM - COMPR. ESPECIAL | D14: 1.95 | I14: 2 | J14: 1.23 | K14: 46182 | L14: 46182 | M14: =L14+2 -> 46184 | N14: mp-ok | O14: 1.282 | P14: 0022.36231 | Q14: COMPRIMENTO ESPECIAL
B15: PRZ10140 | C15: PERFIL U ENRIJ ZC 1,95 X 150 X 60 X 20 MM | D15: 1.95 | I15: 10 | J15: 24.535 | K15: 46183 | L15: 46183 | M15: =L15+2 -> 46185 | N15: mp-ok | O15: =-1*(IF(VLOOKUP(B15,Estoque!B:J,8,FALSE)>0,0,VLOOKUP(B15,Estoque!B:J,8))) -> 0 | P15: 0022.36231
B16: PRF10050 | C16: PERFIL U ENRIJ LQ 2,00 X 150 X 60 X 20 MM | D16: 2 | I16: 50 | J16: 48.25 | K16: 46183 | L16: 46183 | M16: =L16+2 -> 46185 | N16: mp-ok | O16: =-1*(IF(VLOOKUP(B16,Estoque!B:J,8,FALSE)>0,0,VLOOKUP(B16,Estoque!B:J,8))) -> 0 | P16: 0022.36233
B17: PRF10170 | C17: PERFIL U ENRIJ LQ 2,65 X 150 X 60 X 20 MM | D17: 2.65 | I17: 30 | J17: 49.08 | K17: 46183 | L17: 46183 | M17: =L17+2 -> 46185 | N17: mp-ok | O17: =-1*(IF(VLOOKUP(B17,Estoque!B:J,8,FALSE)>0,0,VLOOKUP(B17,Estoque!B:J,8))) -> 0 | P17: 0022.36234
B18: PRF102301 | C18: PERFIL U ENRIJ LQ 3,00 X 150 X 60 X 20 MM - COMPR. ESPECIAL | D18: 3 | I18: 10 | J18: 8.542 | K18: 46184 | L18: 46184 | M18: =L18+4 -> 46188 | N18: MP-ok | O18: 8.58 | P18: 0022.36235 | Q18: COMPRIMENTO ESPECIAL
B19: PRF10230 | C19: PERFIL U ENRIJ LQ 3,00 X 150 X 60 X 20 MM | D19: 3 | I19: 50 | J19: 58.072 | K19: 46184 | L19: 46184 | M19: =L19+4 -> 46188 | N19: mp-ok | O19: 0 | P19: 0022.36235
B20: PRF10244 | C20: PERFIL U ENRIJ LQ 3,35 X 150 X 60 X 20 MM | D20: 3.35 | I20: 10 | J20: 10.59 | K20: 46185 | L20: 46185 | M20: 46185 | N20: mp-ok | O20: 0 | P20: 0022.36236
B21: PRF10009 | C21: PERFIL U ENRIJ LQ 1,80 X 150 X 50 X 20 MM | D21: 1.8 | I21: 10 | J21: 12.46 | K21: 46188 | L21: 46188 | M21: =L25+2 -> 46191 | N21: mp-ok | O21: =-1*(IF(VLOOKUP(B21,Estoque!B:J,8,FALSE)>0,0,VLOOKUP(B21,Estoque!B:J,8))) -> 5.1482 | P21: 0022.36303
B22: PRF10051 | C22: PERFIL U ENRIJ LQ 2,00 X 150 X 50 X 20 MM | D22: 2 | I22: 25 | J22: 9.255 | K22: 46188 | L22: 46188 | N22: mp-ok | O22: =-1*(IF(VLOOKUP(B22,Estoque!B:J,8,FALSE)>0,0,VLOOKUP(B22,Estoque!B:J,8))) -> 10.7693 | P22: 0022.36302
B23: PRF101111 | C23: PERFIL U ENRIJ LQ 2,25 X 150 X 50 X 20 MM - COMPR. ESPECIAL | D23: 2.25 | I23: 3 | K23: 46188 | L23: 46188 | N23: mp-ok | O23: 1.67 | P23: 0022.36301 | Q23: COMPRIMENTO ESPECIAL
B24: PRF10111 | C24: PERFIL U ENRIJ LQ 2,25 X 150 X 50 X 20 MM | D24: 2.25 | I24: 10 | K24: 46188 | L24: 46188 | N24: 2t-ok | O24: =-1*(IF(VLOOKUP(B24,Estoque!B:J,8,FALSE)>0,0,VLOOKUP(B24,Estoque!B:J,8))) -> 0 | P24: 0022.36301
B25: PRF10171 | C25: PERFIL U ENRIJ LQ 2,65 X 150 X 50 X 20 MM | D25: 2.65 | I25: 25 | K25: 46189 | L25: 46189 | N25: MP-OK | O25: 8.058 | P25: 0022.36300
B26: PRF10229 | C26: PERFIL U ENRIJ LQ 3,00 X 150 X50 X 20 MM | D26: 3 | I26: 30 | K26: 46189 | L26: 46189 | N26: MP | O26: =-1*(IF(VLOOKUP(B26,Estoque!B:J,8,FALSE)>0,0,VLOOKUP(B26,Estoque!B:J,8))) -> 7.7983 | P26: 0022.36337
B27: PRF10288 | C27: PERFIL U SIMPLES LQ 1,80 X 150 X 50 MM | D27: 1.8 | I27: 10 | K27: 46190 | L27: 46190 | M27: =L27+3 -> 46193 | N27: 5t-ok | O27: =-1*(IF(VLOOKUP(B27,Estoque!B:J,8,FALSE)>0,0,VLOOKUP(B27,Estoque!B:J,8))) -> 0 | P27: 0022.36338
B28: PRF10360 | C28: PERFIL U SIMPLES LQ 2,00 X 150 X 50 MM | D28: 2 | I28: 10 | K28: 46190 | L28: 46190 | M28: =L28+3 -> 46193 | N28: mp-ok | O28: =-1*(IF(VLOOKUP(B28,Estoque!B:J,8,FALSE)>0,0,VLOOKUP(B28,Estoque!B:J,8))) -> 0.2384 | P28: 0022.36339
B29: PRF10450 | C29: PERFIL U SIMPLES LQ 2,25 X 150 X 50 MM | D29: 2.25 | I29: 25 | K29: 46190 | L29: 46190 | M29: =L29+2 -> 46192 | O29: =-1*(IF(VLOOKUP(B29,Estoque!B:J,8,FALSE)>0,0,VLOOKUP(B29,Estoque!B:J,8))) -> 0 | P29: 0022.36340
B30: PRF10540 | C30: PERFIL U SIMPLES LQ 2,65 X 150 X 50 MM | D30: 2.65 | I30: 20 | K30: 46191 | L30: 46191 | M30: =L30+3 -> 46194 | O30: =-1*(IF(VLOOKUP(B30,Estoque!B:J,8,FALSE)>0,0,VLOOKUP(B30,Estoque!B:J,8))) -> 0.115 | P30: 0022.36341
B31: PRF10816 | C31: PERFIL U SIMPLES LQ 2,65 X 150 X 50 MM COR400 | D31: 2.65 | I31: 10 | K31: 46191 | L31: 46191 | M31: 46192 | N31: MP | O31: 4.4376 | P31: 0022.36382 | Q31: COR30
B32: PRF10630 | C32: PERFIL U SIMPLES LQ 3,00 X 150 X 50 MM | D32: 3 | I32: 70 | K32: 46191 | L32: 46192 | M32: =L32+2 -> 46194 | N32: 19t-ok | O32: =-1*(IF(VLOOKUP(B32,Estoque!B:J,8,FALSE)>0,0,VLOOKUP(B32,Estoque!B:J,8))) -> 10.4154 | P32: 0022.36342
B33: PRF10690 | C33: PERFIL U SIMPLES LQ 4,75 X 150 X 50 MM | D33: 4.75 | I33: 50 | K33: 46195 | L33: 46195 | N33: MP | O33: =-1*(IF(VLOOKUP(B33,Estoque!B:J,8,FALSE)>0,0,VLOOKUP(B33,Estoque!B:J,8))) -> 11.8424 | P33: 0022.36403
B34: PRF10342 | C34: PERFIL U SIMPLES LQ 2,00 X 100 X 40 MM | D34: 2 | I34: 25 | K34: 46196 | L34: 46196 | M34: =L34+4 -> 46200 | O34: =-1*(IF(VLOOKUP(B34,Estoque!B:J,8,FALSE)>0,0,VLOOKUP(B34,Estoque!B:J,8))) -> 3.514
B35: PRF10343 | C35: PERFIL U SIMPLES LQ 2,00 X 100 X 50 MM | D35: 2 | I35: 10 | K35: 46196 | L35: 46196 | M35: =L35+4 -> 46200 | O35: =-1*(IF(VLOOKUP(B35,Estoque!B:J,8,FALSE)>0,0,VLOOKUP(B35,Estoque!B:J,8))) -> 3.514
B36: PRZ10344 | C36: PERFIL U SIMPLES ZC 1,95 X 100 X 50 MM | D36: 1.95 | I36: 10 | K36: 46196 | L36: 46196 | M36: =L36+4 -> 46200 | O36: =-1*(IF(VLOOKUP(B36,Estoque!B:J,8,FALSE)>0,0,VLOOKUP(B36,Estoque!B:J,8))) -> 0
B37: PRF10431 | C37: PERFIL U SIMPLES LQ 2,25 X 100 X 40 MM | D37: 2.25 | I37: 10 | K37: 46197 | L37: 46197 | M37: =L37+5 -> 46202 | O37: =-1*(IF(VLOOKUP(B37,Estoque!B:J,8,FALSE)>0,0,VLOOKUP(B37,Estoque!B:J,8))) -> 1.283
B38: PRF10430 | C38: PERFIL U SIMPLES LQ 2,25 X 100 X 50 MM | D38: 2.25 | I38: 20 | K38: 46197 | L38: 46197 | M38: =L38+5 -> 46202 | O38: =-1*(IF(VLOOKUP(B38,Estoque!B:J,8,FALSE)>0,0,VLOOKUP(B38,Estoque!B:J,8))) -> 4.987
B39: PRF10521 | C39: PERFIL U SIMPLES LQ 2,65 X 100 X 40 MM | D39: 2.65 | I39: 40 | K39: 46197 | L39: 46198 | M39: =L39+5 -> 46203 | O39: 2.138
B40: PRF10522 | C40: PERFIL U SIMPLES LQ 2,65 X 100 X 50 MM | D40: 2.65 | I40: 81 | K40: 46198 | L40: 46199 | M40: =L40+3 -> 46202 | O40: =-1*(IF(VLOOKUP(B40,Estoque!B:J,8,FALSE)>0,0,VLOOKUP(B40,Estoque!B:J,8))) -> 15.8112
...

Sheet memoria
A1: Programação Perfiladeira U 4,75 MM - Junho 2026 | G1: META TOTAL | K1: 1500 | L1: DATA
G2: METAL PERFIL 3/16 | K2: 900 | L2: 46185
A3: Código | B3: Descrição do Perfil | C3: Esp. | D3: Tonelada | E3: Data | G3: Data | H3: Tonelada | I3: OBSERVAÇÕES | K3: Pedidos | L3: Estoque Slitter
D4: Programada | E4: Prevista | G4: Prevista | H4: Realizada | K4: de Venda
D5: =SUM(D6:D40) -> 706 | E5: Comercial | F5: PEDIDO | G5: Produção | H5: =SUM(H6:H487) -> 397.071 | K5: =SUM(K6:K484) -> 164.5371
A6: ='Dados Programa'!B4 -> PRF10255 | B6: ='Dados Programa'!C4 -> PERFIL U ENRIJ LQ 3,00 X 200 X 75 X 20 MM | C6: ='Dados Programa'!D4 -> 3 | D6: ='Dados Programa'!I4 -> 10 | E6: =G6+3 -> 46177 | F6: closed | G6: ='Dados Programa'!L4 -> 46174 | H6: ='Dados Programa'!J4 -> 12.07 | I6: ='Dados Programa'!Q4 -> 0 | J6: ='Dados Programa'!P4 -> 0022.36086 | K6: ='Dados Programa'!O4 -> 0 | L6: ='Dados Programa'!N4 -> mp-ok
A7: ='Dados Programa'!B5 -> PRF10246 | B7: ='Dados Programa'!C5 -> PERFIL U ENRIJ LQ 3,35 X 200 X 75 X 20 MM | C7: ='Dados Programa'!D5 -> 3.35 | D7: ='Dados Programa'!I5 -> 10 | E7: =G7+3 -> 46178 | F7: closed | G7: ='Dados Programa'!L5 -> 46175 | H7: ='Dados Programa'!J5 -> 8.483 | I7: ='Dados Programa'!Q5 -> 0 | J7: ='Dados Programa'!P5 -> 0022.36242 | K7: ='Dados Programa'!O5 -> 5.236 | L7: ='Dados Programa'!N5 -> mp-ok
A8: ='Dados Programa'!B6 -> PRF10120 | B8: ='Dados Programa'!C6 -> PERFIL U ENRIJ LQ 2,25 X 200 X 75 X 20 MM | C8: ='Dados Programa'!D6 -> 2.25 | D8: ='Dados Programa'!I6 -> 20 | E8: =G8+3 -> #VALUE! | F8: closed | G8: ='Dados Programa'!L6 -> - | H8: ='Dados Programa'!J6 -> 6.004 | I8: ='Dados Programa'!Q6 -> 0 | J8: ='Dados Programa'!P6 -> 0022.36100 | K8: ='Dados Programa'!O6 -> 0 | L8: ='Dados Programa'!N6 -> 6t-ok (SEM MP)
A9: ='Dados Programa'!B7 -> PRF10060 | B9: ='Dados Programa'!C7 -> PERFIL U ENRIJ LQ 2,00 X 200 X 75 X 20 MM | C9: ='Dados Programa'!D7 -> 2 | D9: ='Dados Programa'!I7 -> 35 | E9: =G9+3 -> 46179 | F9: closed | G9: ='Dados Programa'!L7 -> 46176 | H9: ='Dados Programa'!J7 -> 34.365 | I9: ='Dados Programa'!Q7 -> 0 | J9: ='Dados Programa'!P7 -> 0022.36101 | K9: ='Dados Programa'!O7 -> 0 | L9: ='Dados Programa'!N7 -> 31t-ok
A10: ='Dados Programa'!B8 -> PRF10180 | B10: ='Dados Programa'!C8 -> PERFIL U ENRIJ LQ 2,65 X 200 X 75 X 20 MM | C10: ='Dados Programa'!D8 -> 2.65 | D10: ='Dados Programa'!I8 -> 25 | E10: =G10+3 -> 46181 | F10: closed | G10: ='Dados Programa'!L8 -> 46178 | H10: ='Dados Programa'!J8 -> 22.46 | I10: ='Dados Programa'!Q8 -> 0 | J10: ='Dados Programa'!P8 -> 0022.36103 | K10: ='Dados Programa'!O8 -> 0.67 | L10: ='Dados Programa'!N8 -> mp-ok
A11: ='Dados Programa'!B9 -> PRF10370 | B11: ='Dados Programa'!C9 -> PERFIL U SIMPLES LQ 2,00 X 200 X 50 MM | C11: ='Dados Programa'!D9 -> 2 | D11: ='Dados Programa'!I9 -> 10 | E11: =G11+3 -> 46184 | F11: closed | G11: ='Dados Programa'!L9 -> 46181 | H11: ='Dados Programa'!J9 -> 11.56 | I11: ='Dados Programa'!Q9 -> 0 | J11: ='Dados Programa'!P9 -> 0022.36104 | K11: ='Dados Programa'!O9 -> 0 | L11: ='Dados Programa'!N9 -> mp-ok
A12: ='Dados Programa'!B10 -> PRF10550 | B12: ='Dados Programa'!C10 -> PERFIL U SIMPLES LQ 2,65 X 200 X 50 MM | C12: ='Dados Programa'!D10 -> 2.65 | D12: ='Dados Programa'!I10 -> 15 | E12: =G12+3 -> 46184 | F12: closed | G12: ='Dados Programa'!L10 -> 46181 | H12: ='Dados Programa'!J10 -> 24.13 | I12: ='Dados Programa'!Q10 -> 0 | J12: ='Dados Programa'!P10 -> 0022.36105 | K12: ='Dados Programa'!O10 -> 0 | L12: ='Dados Programa'!N10 -> mp-ok
A13: ='Dados Programa'!B11 -> PRF10642 | B13: ='Dados Programa'!C11 -> PERFIL U SIMPLES LQ 3,00 X 200 X 50 MM | C13: ='Dados Programa'!D11 -> 3 | D13: ='Dados Programa'!I11 -> 30 | E13: =G13+3 -> 46184 | F13: closed | G13: ='Dados Programa'!L11 -> 46181 | H13: ='Dados Programa'!J11 -> 38.03 | I13: ='Dados Programa'!Q11 -> 0 | J13: ='Dados Programa'!P11 -> 0022.36106 | K13: ='Dados Programa'!O11 -> 0 | L13: ='Dados Programa'!N11 -> mp-ok
A14: ='Dados Programa'!B12 -> PRF100081 | B14: ='Dados Programa'!C12 -> PERFIL U ENRIJ LQ 1,80 X 150 X 60 X 20 MM - COMPR. ESPECIAL | C14: ='Dados Programa'!D12 -> 1.8 | D14: ='Dados Programa'!I12 -> 16 | E14: =G14+3 -> 46185 | F14: closed | G14: ='Dados Programa'!L12 -> 46182 | H14: ='Dados Programa'!J12 -> 14.4596 | I14: ='Dados Programa'!Q12 -> COMPRIMENTO ESPECIAL | J14: ='Dados Programa'!P12 -> 0022.36230 | K14: ='Dados Programa'!O12 -> 14.4596 | L14: ='Dados Programa'!N12 -> mp-ok
A15: ='Dados Programa'!B13 -> PRF10008 | B15: ='Dados Programa'!C13 -> PERFIL U ENRIJ LQ 1,80 X 150 X 60 X 20 MM | C15: ='Dados Programa'!D13 -> 1.8 | D15: ='Dados Programa'!I13 -> 0 | E15: =G15+3 -> #VALUE! | F15: closed | G15: ='Dados Programa'!L13 -> - | H15: ='Dados Programa'!J13 -> 3.4954 | I15: ='Dados Programa'!Q13 -> 0 | J15: ='Dados Programa'!P13 -> 0022.36230 | K15: ='Dados Programa'!O13 -> 0 | L15: ='Dados Programa'!N13 -> passou porque tinha no chão
A16: ='Dados Programa'!B14 -> PRZ101401 | B16: ='Dados Programa'!C14 -> PERFIL U ENRIJ ZC 1,95 X 150 X 60 X 20 MM - COMPR. ESPECIAL | C16: ='Dados Programa'!D14 -> 1.95 | D16: ='Dados Programa'!I14 -> 2 | E16: =G16+3 -> 46185 | F16: closed | G16: ='Dados Programa'!L14 -> 46182 | H16: ='Dados Programa'!J14 -> 1.23 | I16: ='Dados Programa'!Q14 -> COMPRIMENTO ESPECIAL | J16: ='Dados Programa'!P14 -> 0022.36231 | K16: ='Dados Programa'!O14 -> 1.282 | L16: ='Dados Programa'!N14 -> mp-ok
A17: ='Dados Programa'!B15 -> PRZ10140 | B17: ='Dados Programa'!C15 -> PERFIL U ENRIJ ZC 1,95 X 150 X 60 X 20 MM | C17: ='Dados Programa'!D15 -> 1.95 | D17: ='Dados Programa'!I15 -> 10 | E17: =G17+3 -> 46186 | F17: closed | G17: ='Dados Programa'!L15 -> 46183 | H17: ='Dados Programa'!J15 -> 24.535 | I17: ='Dados Programa'!Q15 -> 0 | J17: ='Dados Programa'!P15 -> 0022.36231 | K17: ='Dados Programa'!O15 -> 0 | L17: ='Dados Programa'!N15 -> mp-ok
... A44: ='Dados Programa'!B42 -> PRF10612 | B44: ='Dados Programa'!C42 -> PERFIL U SIMPLES LQ 3,00 X 100 X 50 MM | C44: ='Dados Programa'!D42 -> 3 | D44: ='Dados Programa'!I42 -> 40 | E44: =G44+3 -> 46206 | F44: closed | G44: ='Dados Programa'!L42 -> 46203 | H44: ='Dados Programa'!J42 -> 0 | I44: ='Dados Programa'!Q42 -> 0 | J44: ='Dados Programa'!P42 -> 0 | K44: ='Dados Programa'!O42 -> 5.3503 | L44: ='Dados Programa'!N42 -> 0
A45: ='Dados Programa'!B44 -> PMG10130 | B45: ='Dados Programa'!C44 -> PERFIL U SIMPLES – 1,95 X 75 X 40 MAGNELIS ZM310 | C45: ='Dados Programa'!D44 -> 1.95 | D45: ='Dados Programa'!I44 -> 20 | E45: =G45+3 -> 46207 | F45: closed | G45: ='Dados Programa'!L44 -> 46204 | H45: ='Dados Programa'!J44 -> 0 | I45: ='Dados Programa'!Q44 -> MAGNELIS ZM310 | J45: ='Dados Programa'!P44 -> 0 | K45: ='Dados Programa'!O44 -> 17.55 | L45: ='Dados Programa'!N44 -> 0
A46: ='Dados Programa'!B45 -> PRF10321 | B46: ='Dados Programa'!C45 -> PERFIL U SIMPLES LQ 2,00 X 75 X 40 MM | C46: ='Dados Programa'!D45 -> 2 | D46: ='Dados Programa'!I45 -> 25 | E46: =G46+3 -> 46208 | F46: closed | G46: ='Dados Programa'!L45 -> 46205 | H46: ='Dados Programa'!J45 -> 0 | I46: ='Dados Programa'!Q45 -> 0 | J46: ='Dados Programa'!P45 -> 0 | K46: ='Dados Programa'!O45 -> 0 | L46: ='Dados Programa'!N45 -> 0
A47: ='Dados Programa'!B46 -> PRF10500 | B47: ='Dados Programa'!C46 -> PERFIL U SIMPLES LQ 2,65 X 75 X 40 MM | C47: ='Dados Programa'!D46 -> 2.65 | D47: ='Dados Programa'!I46 -> 25 | E47: =G47+3 -> 46208 | F47: closed | G47: ='Dados Programa'!L46 -> 46205 | H47: ='Dados Programa'!J46 -> 0 | I47: ='Dados Programa'!Q46 -> 0 | J47: ='Dados Programa'!P46 -> 0 | K47: ='Dados Programa'!O46 -> 0 | L47: ='Dados Programa'!N46 -> 0
A48: ='Dados Programa'!B47 -> PRF10710 | B48: ='Dados Programa'!C47 -> PERFIL U SIMPLES LQ 3,75 X 75 X 40 MM | C48: ='Dados Programa'!D47 -> 3.75 | D48: ='Dados Programa'!I47 -> 10 | E48: =G48+3 -> 46209 | F48: closed | G48: ='Dados Programa'!L47 -> 46206 | H48: ='Dados Programa'!J47 -> 0 | I48: ='Dados Programa'!Q47 -> 0 | J48: ='Dados Programa'!P47 -> 0 | K48: ='Dados Programa'!O47 -> 0.9931 | L48: ='Dados Programa'!N47 -> 0
A49: ='Dados Programa'!B48 -> PRF10651 | B49: ='Dados Programa'!C48 -> PERFIL U SIMPLES LQ 4,75 X 75 X 40 MM | C49: ='Dados Programa'!D48 -> 4.75 | D49: ='Dados Programa'!I48 -> 40 | E49: =G49+3 -> 46212 | F49: closed | G49: ='Dados Programa'!L48 -> 46209 | H49: ='Dados Programa'!J48 -> 0 | I49: ='Dados Programa'!Q48 -> 0 | J49: ='Dados Programa'!P48 -> 0 | K49: ='Dados Programa'!O48 -> 1.0138 | L49: ='Dados Programa'!N48 -> 0
A50: ='Dados Programa'!B49 -> PRF10005 | B50: ='Dados Programa'!C49 -> PERFIL U ENRIJ LQ 1,80 X 75 X 40 X 15 MM | C50: ='Dados Programa'!D49 -> 1.8 | D50: ='Dados Programa'!I49 -> 20 | E50: =G50+3 -> 46213 | F50: closed | G50: ='Dados Programa'!L49 -> 46210 | H50: ='Dados Programa'!J49 -> 0 | I50: ='Dados Programa'!Q49 -> 0 | J50: ='Dados Programa'!P49 -> 0 | K50: ='Dados Programa'!O49 -> 0 | L50: ='Dados Programa'!N49 -> 0
A51: ='Dados Programa'!B50 -> PRF100201 | B51: ='Dados Programa'!C50 -> PERFIL U ENRIJ LQ 2,00 X 75 X 40 X 15 MM - COMPR. ESPECIAL | C51: ='Dados Programa'!D50 -> 2 | D51: ='Dados Programa'!I50 -> 5 | E51: =G51+3 -> 46213 | F51: closed | G51: ='Dados Programa'!L50 -> 46210 | H51: ='Dados Programa'!J50 -> 0 | I51: ='Dados Programa'!Q50 -> 0 | J51: ='Dados Programa'!P50 -> 0 | K51: ='Dados Programa'!O50 -> 2.3625 | L51: ='Dados Programa'!N50 -> 0
A52: ='Dados Programa'!B51 -> PRF10020 | B52: ='Dados Programa'!C51 -> PERFIL U ENRIJ LQ 2,00 X 75 X 40 X 15 MM | C52: ='Dados Programa'!D51 -> 2 | D52: ='Dados Programa'!I51 -> 35 | E52: =G52+3 -> 46214 | F52: closed | G52: ='Dados Programa'!L51 -> 46211 | H52: ='Dados Programa'!J51 -> 0 | I52: ='Dados Programa'!Q51 -> 0 | J52: ='Dados Programa'!P51 -> 0 | K52: ='Dados Programa'!O51 -> 0 | L52: ='Dados Programa'!N51 -> 0
A53: ='Dados Programa'!B52 -> PRF100801 | B53: ='Dados Programa'!C52 -> PERFIL U ENRIJ LQ 2,25 X 75 X 40 X 15 MM - COMPR. ESPECIAL | C53: ='Dados Programa'!D52 -> 2.25 | D53: ='Dados Programa'!I52 -> 18 | E53: =G53+3 -> 46214 | F53: closed | G53: ='Dados Programa'!L52 -> 46211 | H53: ='Dados Programa'!J52 -> 0 | I53: ='Dados Programa'!Q52 -> 0 | J53: ='Dados Programa'!P52 -> 0 | K53: ='Dados Programa'!O52 -> 15.3 | L53: ='Dados Programa'!N52 -> 0
A54: ='Dados Programa'!B53 -> PRF10080 | B54: ='Dados Programa'!C53 -> PERFIL U ENRIJ LQ 2,25 X 75 X 40 X 15 MM | C54: ='Dados Programa'!D53 -> 2.25 | D54: ='Dados Programa'!I53 -> 20 | E54: =G54+3 -> 46215 | F54: closed | G54: ='Dados Programa'!L53 -> 46212 | H54: ='Dados Programa'!J53 -> 0 | I54: ='Dados Programa'!Q53 -> 0 | J54: ='Dados Programa'!P53 -> 0 | K54: ='Dados Programa'!O53 -> 0 | L54: ='Dados Programa'!N53 -> 0
A55: ='Dados Programa'!B54 -> PRF10140 | B55: ='Dados Programa'!C54 -> PERFIL U ENRIJ LQ 2,65 X 75 X 40 X 15 MM | C55: ='Dados Programa'!D54 -> 2.65 | D55: ='Dados Programa'!I54 -> 20 | E55: =G55+3 -> 46215 | F55: closed | G55: ='Dados Programa'!L54 -> 46212 | H55: ='Dados Programa'!J54 -> 0 | I55: ='Dados Programa'!Q54 -> 0 | J55: ='Dados Programa'!P54 -> 0 | K55: ='Dados Programa'!O54 -> 0 | L55: ='Dados Programa'!N54 -> 0

Sheet rascunho
A1: Estabelecimento | B1: Item | C1: Descrição | D1: Saldo 001A | E1: Saldo Calogi | F1: Pendência de Vendas | G1: Saldo Disponível
A2: 0022_OI_CED_IND | B2: PMG10130 | C2: PERFIL U SIMPLES – 1,95 X 75 X 40 MAGNELIS | D2: 0 | E2: 0 | F2: 17.55 | G2: -17.55
A3: 0022_OI_CED_IND | B3: PMG101301 | C3: PERFIL U SIMPLES – 1,95 X 75 X 40 MAGNELIS - COMP. ESPECIAL | D3: 0 | E3: 0 | F3: 0 | G3: 0
A4: 0022_OI_CED_IND | B4: PMG10132 | C4: PERFIL U SIMPLES – 1,95 X 68 X 30 MAGNELIS | D4: 0 | E4: 0 | F4: 0 | G4: 0
A5: 0022_OI_CED_IND | B5: PMG10134 | C5: PERFIL U ENRIJ 1,95 X 100 X 40 X 17 MM -MAGNELIS | D5: 0 | E5: 0 | F5: 8.865 | G5: -8.865
A6: 0022_OI_CED_IND | B6: PMG10135 | C6: PERFIL U ENRIJ 1,95 X 127 X 50 X 17 MM -MAGNELIS | D6: 0 | E6: 9.442 | F6: 3.39 | G6: 6.052
A7: 0022_OI_CED_IND | B7: PMG10135 | C7: PERFIL U ENRIJ ZC 1,95 X 127 X 50 X 17 MM -MAGNELIS | D7: 0 | E7: 9.442 | F7: 3.39 | G7: 6.052
A8: 0022_OI_CED_IND | B8: PMG10140 | C8: PERFIL U ENRIJ 1,95 X 150 X 60 X 20 MM MAGNELIS | D8: 0 | E8: 0 | F8: 0 | G8: 0
A9: 0022_OI_CED_IND | B9: PMG10142 | C9: PERFIL U ENRIJ – 1,95 X 75 X 40 X 15 MAGNELIS | D9: 0 | E9: 4.674 | F9: 0 | G9: 4.674
A10: 0022_OI_CED_IND | B10: PMG10142 | C10: PERFIL U ENRIJECIDO – 1,95 X 75 X 40 X 15 MAGNELIS | D10: 0 | E10: 4.674 | F10: 0 | G10: 4.674
A11: 0022_OI_CED_IND | B11: PMG101421 | C11: PERFIL U ENRIJ ZC 1,95 X 150 X 60 X 20 MM - COMP. ESPECIAL | D11: 0 | E11: 0 | F11: 0 | G11: 0
A12: 0022_OI_CED_IND | B12: PMG10160 | C12: PERFIL U ENRIJ ZC 1,95 X 200 X 75 X 20 MM -MAGNELIS | D12: 0 | E12: 0 | F12: 0 | G12: 0
A13: 0022_OI_CED_IND | B13: PMG10180 | C13: PERFIL U SIMPLES 2,30 X 92 X 30 MM MAGNELIS | D13: 0 | E13: 0 | F13: 0 | G13: 0
... A393: 0022_OI_CED_IND | B393: PRZ10549 | C393: PERFIL U SIMPLES ZC 3,00 X 100 X 50 MM | D393: 0 | E393: 0.1838 | F393: 0 | G393: 0.1838

Sheet prog im
A1: Item | B1: Descrição | C1: Data | D1: Fornecedor | E1: Qtd
A2: PMG10130 | B2: PERFIL U SIMPLES – 1,95 X 75 X 40 MAGNELIS | C2: 46176 | E2: 18
A3: PMG10134 | B3: PERFIL U ENRIJ 1,95 X 100 X 40 X 17 MM -MAGNELIS | C3: 46176 | E3: 9
A4: PMG10135 | B4: PERFIL U ENRIJ 1,95 X 127 X 50 X 17 MM -MAGNELIS | C4: 46176 | E4: 5
A5: PRF10004 | B5: PERFIL U ENRIJ LQ 1,80 X 50 X 25 X 10 MM | C5: 46176 | E5: 12
A6: PRF10005 | B6: PERFIL U ENRIJ LQ 1,80 X 75 X 40 X 15 MM | C6: 46176 | E6: 19
A7: PRF10006 | B7: PERFIL U ENRIJ LQ 1,80 X 100 X 50 X 17 MM | C7: 46176 | E7: 23
A8: PRF10009 | B8: PERFIL U ENRIJ LQ 1,80 X 150 X 50 X 20 MM | C8: 46176 | E8: 5
A9: PRF10020 | B9: PERFIL U ENRIJ LQ 2,00 X 75 X 40 X 15 MM | C9: 46176 | E9: 35
A10: PRF10022 | B10: PERFIL U ENRIJ LQ 1,80 X 100 X 40 X 17 MM | C10: 46176 | E10: 48
A11: PRF10031 | B11: PERFIL U ENRIJ LQ 2,00 X 100 X 40 X 17 MM | C11: 46176 | E11: 65
A12: PRF10032 | B12: PERFIL U ENRIJ LQ 2,00 X 100 X 50 X 17 MM | C12: 46176 | E12: 71
A13: PRF10050 | B13: PERFIL U ENRIJ LQ 2,00 X 150 X 60 X 20 MM | C13: 46176 | E13: 59
... A57: PRZ10120 | B57: PERFIL U ENRIJ ZC 1,95 X 100 X 50 X 17 MM | C57: 46176 | E57: 26

Sheet Faturamento
C1: 42370 | D1: 42401 | E1: 42430 | F1: 42461 | G1: 42491 | H1: 42522 | I1: 42552 | J1: 42583 | K1: 42614 | L1: 42644 | M1: 42675 | N1: 42705 | O1: 42736 | P1: 42767 | Q1: 42795 | R1: 42826 | S1: 42856 | T1: 42887 | U1: 42917 | V1: 42948 | W1: 42979 | X1: 43009 | Y1: 43040 | Z1: 43070 | AA1: 43101 | AB1: 43132 | AC1: 43160 | AD1: 43191 | AE1: 43221 | AF1: 43252 | AG1: 43282 | AH1: 43313 | AI1: 43344 | AJ1: 43374 | AK1: 43405 | AL1: 43435 | AM1: 43466 | AN1: 43497 | AO1: 43525 | AP1: 43556 | AQ1: 43586 | AR1: 43617 | AS1: 43647 | AT1: 43678 | AU1: 43709 | AV1: 43739 | AW1: 43770 | AX1: 43800 | AY1: 43831 | AZ1: 43862 | BA1: 43891 | BB1: 43922 | BC1: 43952 | BD1: 43983 | BE1: 44013 | BF1: 44044 | BG1: 44075 | BH1: 44105 | BI1: 44136 | BJ1: 44166 | BK1: 44197 | BL1: 44228 | BM1: 44256 | BN1: 44287 | BO1: 44317 | BP1: 44348 | BQ1: 44378 | BR1: 44409 | BS1: 44440 | BT1: 44470 | BU1: 44501 | BV1: 44531 | BW1: 44562 | BX1: 44593 | BY1: 44621 | BZ1: 44652 | CA1: 44682 | CB1: 44713 | CC1: 44743 | CD1: 44774 | CE1: 44805 | CF1: 44835 | CG1: 44866 | CH1: 44896 | CI1: 44927 | CJ1: 44958 | CK1: 44986 | CL1: 45017 | CM1: 45047 | CN1: 45078 | CO1: 45108 | CP1: 45139 | CQ1: 45170 | CR1: 45200 | CS1: 45231 | CT1: 45261 | CU1: 45292 | CV1: 45323 | CW1: 45352 | CX1: 45383 | CY1: 45413 | CZ1: 45444 | DA1: 45474 | DB1: 45505 | DC1: 45536 | DD1: 45566 | DE1: 45597 | DF1: 45627 | DG1: 45658 | DH1: 45689 | DI1: 45717 | DJ1: 45748 | DK1: 45778 | DL1: 45809 | DM1: 45839 | DN1: 45870 | DO1: 45901 | DP1: 45931 | DQ1: 45962 | DR1: 45992 | DS1: 46023 | DT1: 46054 | DU1: 46082 | DV1: 46113 | DW1: 46143 | DX1: Média de Venda Semestre | DY1: Estoque p/ 45 dias | DZ1: Sugestão de Programação | EA1: Estoque Atual | EB1: Programado
A2: Item | B2: Descrição | C2: =SUM(C3:C284) -> 388.1275 | D2: =SUM(D3:D284) -> 364.6075 | E2: =SUM(E3:E284) -> 626.6115 | F2: =SUM(F3:F284) -> 495.3549 | G2: =SUM(G3:G284) -> 231.1674 | H2: =SUM(H3:H284) -> 300.7712 | I2: =SUM(I3:I284) -> 293.9931 | J2: =SUM(J3:J284) -> 355.9513 | ... DW2: =SUM(DW3:DW284) -> 1342.8437 | DX2: =SUM(DX3:DX472) -> 1354.8621 | DY2: =SUM(DY3:DY472) -> 2032.2932 | EA2: =SUBTOTAL(9,EA3:EA278) -> #N/A | EB2: =SUBTOTAL(9,EB3:EB263) -> #N/A | EC2: 1° Produção | ED2: 2° Produção | EE2: 3° Produção
A3: PRF10001 | B3: PERFIL U SIMPLES LQ 1,50 X 68 X 30 MM | AO3: 7.2 | BD3: 5 | BG3: 1.58 | BH3: 6.66 | BI3: 4.69 | BJ3: 5.918 | BK3: 1.58 | BL3: 1.74 | BM3: 0.42 | CK3: 7 | CR3: 0.189 | CT3: 0.45 | CU3: =IFERROR(VLOOKUP(A3,'fat-01-24'!A:C,3,FALSE),"") | CV3: =IFERROR(VLOOKUP(A3,'fat-02-24'!A:C,3,FALSE),"") -> 3.766 | CW3: =IFERROR(VLOOKUP(A3,'fat-03-24'!A:C,3,FALSE),"") | CX3: =IFERROR(VLOOKUP(A3,'fat-04-24'!A:C,3,FALSE),"") | CY3: =IFERROR(VLOOKUP(A3,'fat-05-24'!A:C,3,FALSE),"") | CZ3: =IFERROR(VLOOKUP(A3,'fat-06-24'!A:C,3,FALSE),"") | DA3: =IFERROR(VLOOKUP(A3,'fat-07-24'!A:C,3,FALSE),"") | DB3: =IFERROR(VLOOKUP(A3,'fat-08-24'!A:D,3,FALSE),"") | DC3: =IFERROR(VLOOKUP(A3,'fat-09-24'!A:C,3,FALSE),"") | DD3: =IFERROR(VLOOKUP(A3,'fat-10-24'!A:C,3,FALSE),"") -> 11.189 | DE3: =IFERROR(VLOOKUP(A3,'fat-11-24'!A:C,3,FALSE),"") -> 0 | DF3: =IFERROR(VLOOKUP(A3,'fat-12-24'!A:D,3,FALSE),"") -> 28.474 | DG3: =IFERROR(VLOOKUP(A3,'fat-01-25'!A:D,3,FALSE),"") -> 5.222 | DH3: =IFERROR(VLOOKUP(A3,'fat-02-25'!A:D,3,FALSE),"") -> 0 | DI3: =IFERROR(VLOOKUP(A3,'fat-03-25'!A:C,3,FALSE),"") -> 0 | DJ3: =IFERROR(VLOOKUP(A3,'fat-04-25'!A:C,3,FALSE),"") -> 5 | DK3: =IFERROR(VLOOKUP(A3,'fat-02-25'!A:C,3,FALSE),"") -> 0 | DL3: =IFERROR(VLOOKUP(A3,'fat-06-25'!A:C,3,FALSE),"") -> 0 | DM3: =IFERROR(VLOOKUP(A3,'fat-05-25'!A:C,3,FALSE),"") -> 0.468 | DN3: =IFERROR(VLOOKUP(A3,'fat-08-25'!A:C,3,FALSE),"") -> 7.46 | DO3: =IFERROR(VLOOKUP(A3,'fat-09-25'!A:C,3,FALSE),"") -> 0 | DP3: =IFERROR(VLOOKUP(A3,'fat-10-25'!A:C,3,FALSE),"") -> 5.272 | DQ3: =IFERROR(VLOOKUP(A3,'fat-11-25'!A:D,3,FALSE),"") | DR3: =IFERROR(VLOOKUP(A3,'fat-12-25'!A:D,3,FALSE),"") | DS3: =IFERROR(VLOOKUP(A3,'fat-01-26'!A:C,3,FALSE),"") | DT3: =IFERROR(VLOOKUP(A3,'fat-02-26'!A:C,3,FALSE),"") | DU3: =IFERROR(VLOOKUP(A3,'fat-03-26'!A:C,3,FALSE),"") | DV3: =IFERROR(VLOOKUP(A3,'fat-04-26'!A:C,3,FALSE),"") | DW3: =IFERROR(VLOOKUP(A3,'fat-05-26'!A:C,3,FALSE),"") | DX3: =SUM(DR3:DW3)/6 -> 0 | DY3: =DX3/30*45 -> 0 | EA3: =VLOOKUP(A3,Estoque!B:I,8,FALSE) -> 0.002 | EB3: =VLOOKUP(A3,Estoque!B:N,13,FALSE) -> 0
A4: PRF10002 | B4: PERFIL U SIMPLES LQ 1,50 X 100 X 40 MM | CU4: =IFERROR(VLOOKUP(A4,'fat-01-24'!A:C,3,FALSE),"") | CV4: =IFERROR(VLOOKUP(A4,'fat-02-24'!A:C,3,FALSE),"") | CW4: =IFERROR(VLOOKUP(A4,'fat-03-24'!A:C,3,FALSE),"") | CX4: =IFERROR(VLOOKUP(A4,'fat-04-24'!A:C,3,FALSE),"") | CY4: =IFERROR(VLOOKUP(A4,'fat-05-24'!A:C,3,FALSE),"") | CZ4: =IFERROR(VLOOKUP(A4,'fat-06-24'!A:C,3,FALSE),"") | DA4: =IFERROR(VLOOKUP(A4,'fat-07-24'!A:C,3,FALSE),"") | DB4: =IFERROR(VLOOKUP(A4,'fat-08-24'!A:D,3,FALSE),"") | DC4: =IFERROR(VLOOKUP(A4,'fat-09-24'!A:C,3,FALSE),"") | DD4: =IFERROR(VLOOKUP(A4,'fat-10-24'!A:C,3,FALSE),"") | DE4: =IFERROR(VLOOKUP(A4,'fat-11-24'!A:C,3,FALSE),"") | DF4: =IFERROR(VLOOKUP(A4,'fat-12-24'!A:D,3,FALSE),"") | DG4: =IFERROR(VLOOKUP(A4,'fat-01-25'!A:D,3,FALSE),"") | DH4: =IFERROR(VLOOKUP(A4,'fat-02-25'!A:D,3,FALSE),"") | DI4: =IFERROR(VLOOKUP(A4,'fat-03-25'!A:C,3,FALSE),"") | DJ4: =IFERROR(VLOOKUP(A4,'fat-04-25'!A:C,3,FALSE),"") | DK4: =IFERROR(VLOOKUP(A4,'fat-02-25'!A:C,3,FALSE),"") | DL4: =IFERROR(VLOOKUP(A4,'fat-06-25'!A:C,3,FALSE),"") | DM4: =IFERROR(VLOOKUP(A4,'fat-05-25'!A:C,3,FALSE),"") | DN4: =IFERROR(VLOOKUP(A4,'fat-08-25'!A:C,3,FALSE),"") | DO4: =IFERROR(VLOOKUP(A4,'fat-09-25'!A:C,3,FALSE),"") | DP4: =IFERROR(VLOOKUP(A4,'fat-10-25'!A:C,3,FALSE),"") | DQ4: =IFERROR(VLOOKUP(A4,'fat-11-25'!A:D,3,FALSE),"") | DR4: =IFERROR(VLOOKUP(A4,'fat-12-25'!A:D,3,FALSE),"") | DS4: =IFERROR(VLOOKUP(A4,'fat-01-26'!A:C,3,FALSE),"") | DT4: =IFERROR(VLOOKUP(A4,'fat-02-26'!A:C,3,FALSE),"") | DU4: =IFERROR(VLOOKUP(A4,'fat-03-26'!A:C,3,FALSE),"") | DV4: =IFERROR(VLOOKUP(A4,'fat-04-26'!A:C,3,FALSE),"") | DW4: =IFERROR(VLOOKUP(A4,'fat-05-26'!A:C,3,FALSE),"") | DX4: =SUM(DR4:DW4)/6 -> 0 | DY4: =DX4/30*45 -> 0 | EA4: =VLOOKUP(A4,Estoque!B:I,8,FALSE) -> 0 | EB4: =VLOOKUP(A4,Estoque!B:N,13,FALSE) -> 0
A5: PRF10003 | B5: PERFIL U SIMPLES LQ 1,50 X 75 X 40 MM | AO5: 10.88 | AR5: 10.26 | AW5: 4.945 | BG5: 0.41 | CL5: 7 | CT5: 0.55 | CU5: =IFERROR(VLOOKUP(A5,'fat-01-24'!A:C,3,FALSE),"") | CV5: =IFERROR(VLOOKUP(A5,'fat-02-24'!A:C,3,FALSE),"") -> 1.403 | CW5: =IFERROR(VLOOKUP(A5,'fat-03-24'!A:C,3,FALSE),"") | CX5: =IFERROR(VLOOKUP(A5,'fat-04-24'!A:C,3,FALSE),"") | CY5: =IFERROR(VLOOKUP(A5,'fat-05-24'!A:C,3,FALSE),"") | CZ5: =IFERROR(VLOOKUP(A5,'fat-06-24'!A:C,3,FALSE),"") | DA5: =IFERROR(VLOOKUP(A5,'fat-07-24'!A:C,3,FALSE),"") | DB5: =IFERROR(VLOOKUP(A5,'fat-08-24'!A:D,3,FALSE),"") | DC5: =IFERROR(VLOOKUP(A5,'fat-09-24'!A:C,3,FALSE),"") | DD5: =IFERROR(VLOOKUP(A5,'fat-10-24'!A:C,3,FALSE),"") | DE5: =IFERROR(VLOOKUP(A5,'fat-11-24'!A:C,3,FALSE),"") | DF5: =IFERROR(VLOOKUP(A5,'fat-12-24'!A:D,3,FALSE),"") -> 10.004 | DG5: =IFERROR(VLOOKUP(A5,'fat-01-25'!A:D,3,FALSE),"") -> 2.614 | DH5: =IFERROR(VLOOKUP(A5,'fat-02-25'!A:D,3,FALSE),"") | DI5: =IFERROR(VLOOKUP(A5,'fat-03-25'!A:C,3,FALSE),"") | DJ5: =IFERROR(VLOOKUP(A5,'fat-04-25'!A:C,3,FALSE),"") | DK5: =IFERROR(VLOOKUP(A5,'fat-02-25'!A:C,3,FALSE),"") | DL5: =IFERROR(VLOOKUP(A5,'fat-06-25'!A:C,3,FALSE),"") -> 0 | DM5: =IFERROR(VLOOKUP(A5,'fat-05-25'!A:C,3,FALSE),"") | DN5: =IFERROR(VLOOKUP(A5,'fat-08-25'!A:C,3,FALSE),"") -> 8.89 | DO5: =IFERROR(VLOOKUP(A5,'fat-09-25'!A:C,3,FALSE),"") -> 0 | DP5: =IFERROR(VLOOKUP(A5,'fat-10-25'!A:C,3,FALSE),"") -> 0 | DQ5: =IFERROR(VLOOKUP(A5,'fat-11-25'!A:D,3,FALSE),"") | DR5: =IFERROR(VLOOKUP(A5,'fat-12-25'!A:D,3,FALSE),"") | DS5: =IFERROR(VLOOKUP(A5,'fat-01-26'!A:C,3,FALSE),"") | DT5: =IFERROR(VLOOKUP(A5,'fat-02-26'!A:C,3,FALSE),"") | DU5: =IFERROR(VLOOKUP(A5,'fat-03-26'!A:C,3,FALSE),"") | DV5: =IFERROR(VLOOKUP(A5,'fat-04-26'!A:C,3,FALSE),"") | DW5: =IFERROR(VLOOKUP(A5,'fat-05-26'!A:C,3,FALSE),"") | DX5: =SUM(DR5:DW5)/6 -> 0 | DY5: =DX5/30*45 -> 0 | EA5: =VLOOKUP(A5,Estoque!B:I,8,FALSE) -> 0 | EB5: =VLOOKUP(A5,Estoque!B:N,13,FALSE) -> 0
A6: PRF10004 | B6: PERFIL U ENRIJ LQ 1,80 X 50 X 25 X 10 MM | C6: 12.48 | D6: 11.363 | E6: 6.62 | F6: 6.825 | G6: 0.05 | H6: 3.615 | I6: 3.451 | K6: 7.4 | L6: 2.63 | M6: 6.029 | N6: 6.875 | O6: 2 | P6: 9.68 | Q6: 3.604 | R6: 0.115 | S6: -3.4601 | U6: 2.558 | V6: 3.37 | W6: 0.214 | AB6: 4.165 | AC6: 3.46 | AD6: 0.72 | AE6: 2.673 | AG6: 3.456 | AH6: 0.036 | AI6: 38.289 | AJ6: 8.052 | AK6: 4.156 | AL6: 5.535 | AM6: 7.273 | AN6: 1.725 | AO6: 1.35 | AP6: 6.005 | AQ6: 9.358 | AR6: 0.405 | AS6: 11.635 | AT6: 8.126 | AU6: 14.866 | AV6: 17.271 | AW6: 7.716 | AX6: 2.175 | AY6: 5.594 | AZ6: 13.051 | BA6: 20.135 | BB6: 14.295 | BC6: 8.7807 | BD6: 23.26 | BE6: 28.832 | BF6: 18.6228 | BG6: 26.165 | BH6: 4.953 | BI6: 85.027 | BJ6: 2.919 | BK6: 2.06 | BL6: 24.172 | BM6: 9.256 | BN6: 9.854 | BO6: 57.28 | BP6: 14.025 | BQ6: 5.516 | BR6: 0.51 | BS6: 1.163 | BT6: 0.82 | BU6: 1.74 | BV6: 5.12 | BW6: 3.261 | BX6: 0.56 | BY6: 1.995 | BZ6: 40.433 | CA6: 3.245 | CB6: 0.18 | CD6: 10.4198 | CE6: 12.041 | CF6: 1.16 | CG6: 30.412 | CH6: 0.9 | CI6: -0.316 | CJ6: 0.289 | CK6: 36.336 | CL6: 6.074 | CM6: 19.872 | CN6: 9.759 | CO6: 19.296 | CP6: 4.797 | CQ6: 3.122 | CR6: 4.809 | CS6: 4.2697748 | CT6: 27.574 | CU6: =IFERROR(VLOOKUP(A6,'fat-01-24'!A:C,3,FALSE),"") -> 61.949 | CV6: =IFERROR(VLOOKUP(A6,'fat-02-24'!A:C,3,FALSE),"") -> 13.719 | CW6: =IFERROR(VLOOKUP(A6,'fat-03-24'!A:C,3,FALSE),"") -> 18.363 | CX6: =IFERROR(VLOOKUP(A6,'fat-04-24'!A:C,3,FALSE),"") -> 23.749 | CY6: =IFERROR(VLOOKUP(A6,'fat-05-24'!A:C,3,FALSE),"") -> 11.5411 | CZ6: =IFERROR(VLOOKUP(A6,'fat-06-24'!A:C,3,FALSE),"") -> 9.759 | DA6: =IFERROR(VLOOKUP(A6,'fat-07-24'!A:C,3,FALSE),"") | DB6: =IFERROR(VLOOKUP(A6,'fat-08-24'!A:D,3,FALSE),"") -> 60.965 | DC6: =IFERROR(VLOOKUP(A6,'fat-09-24'!A:C,3,FALSE),"") -> 17.632 | DD6: =IFERROR(VLOOKUP(A6,'fat-10-24'!A:C,3,FALSE),"") -> 25.492 | DE6: =IFERROR(VLOOKUP(A6,'fat-11-24'!A:C,3,FALSE),"") -> 46.023 | DF6: =IFERROR(VLOOKUP(A6,'fat-12-24'!A:D,3,FALSE),"") -> 12.32 | DG6: =IFERROR(VLOOKUP(A6,'fat-01-25'!A:D,3,FALSE),"") -> 33.614 | DH6: =IFERROR(VLOOKUP(A6,'fat-02-25'!A:D,3,FALSE),"") -> 7.722 | DI6: =IFERROR(VLOOKUP(A6,'fat-03-25'!A:C,3,FALSE),"") -> 0.54 | DJ6: =IFERROR(VLOOKUP(A6,'fat-04-25'!A:C,3,FALSE),"") -> 23.785 | DK6: =IFERROR(VLOOKUP(A6,'fat-02-25'!A:C,3,FALSE),"") -> 7.722 | DL6: =IFERROR(VLOOKUP(A6,'fat-06-25'!A:C,3,FALSE),"") -> 7.488 | DM6: =IFERROR(VLOOKUP(A6,'fat-05-25'!A:C,3,FALSE),"") -> 8.678 | DN6: =IFERROR(VLOOKUP(A6,'fat-08-25'!A:C,3,FALSE),"") -> 6.916 | DO6: =IFERROR(VLOOKUP(A6,'fat-09-25'!A:C,3,FALSE),"") -> 8.962 | DP6: =IFERROR(VLOOKUP(A6,'fat-10-25'!A:C,3,FALSE),"") -> 13.032 | DQ6: =IFERROR(VLOOKUP(A6,'fat-11-25'!A:D,3,FALSE),"") -> 18.071 | DR6: =IFERROR(VLOOKUP(A6,'fat-12-25'!A:D,3,FALSE),"") -> 15.32 | DS6: =IFERROR(VLOOKUP(A6,'fat-01-26'!A:C,3,FALSE),"") -> 15.204 | DT6: =IFERROR(VLOOKUP(A6,'fat-02-26'!A:C,3,FALSE),"") -> 14.644 | DU6: =IFERROR(VLOOKUP(A6,'fat-03-26'!A:C,3,FALSE),"") -> 36.637 | DV6: =IFERROR(VLOOKUP(A6,'fat-04-26'!A:C,3,FALSE),"") -> 16.42 | DW6: =IFERROR(VLOOKUP(A6,'fat-05-26'!A:C,3,FALSE),"") -> 4.063 | DX6: =SUM(DR6:DW6)/6 -> 17.048 | DY6: =DX6/30*45 -> 25.572 | EA6: =VLOOKUP(A6,Estoque!B:I,8,FALSE) -> 22.4562 | EB6: =VLOOKUP(A6,Estoque!B:N,13,FALSE) -> 20 | EC6: 90 | ED6: 20 | EE6: 20
A7: PRF10005 | B7: PERFIL U ENRIJ LQ 1,80 X 75 X 40 X 15 MM | C7: 27.08 | D7: 15.99 | E7: 57.49 | F7: 65.5 | G7: 15.46 | H7: 21.52 | I7: 18.515 | J7: 17.955 | K7: 24.855 | M7: 10.135 | N7: 1.685 | P7: 26.405 | Q7: 24.945 | R7: 0.9933 | S7: -11.085 | T7: 1.96 | U7: 4.768 | V7: 11.692 | W7: 3.266 | AA7: 0.028 | AB7: 1.91 | AC7: 10.465 | AD7: 19.242 | AE7: 8.608 | AF7: 11.382 | AG7: 4.822 | AH7: 9.47 | AI7: 70.196 | AJ7: 13.41 | AK7: 16.717 | AL7: 35.033 | AM7: 21.674 | AN7: 54.967 | AO7: 4.897 | AP7: 28.032 | AQ7: 28.603 | AR7: 4.195 | AS7: 52.955 | AT7: 50.27 | AU7: 33.746 | AV7: 58.461 | AW7: 7.513 | AX7: 22.744 | AY7: 26.165 | AZ7: 38.078 | BA7: 28.297 | BB7: 57.167 | BC7: 26.2328 | BD7: 47.236 | BE7: 68.635 | BF7: 40.853 | BG7: 57.58 | BH7: 11.32 | BI7: 67.1652 | BJ7: 21.61 | BK7: 29.143 | BL7: 2.625 | BM7: 68.037 | BN7: 3.5 | BO7: 39.203 | BP7: 21.671 | BQ7: 14.025 | BR7: 7.55 | BS7: 3.5046 | BT7: 1.03 | BU7: 8.161 | BV7: 5.992 | BW7: 15.045 | BX7: 10.065 | BY7: 28.338 | BZ7: 1.3326 | CA7: 49.726 | CB7: 10.208 | CC7: 6.861 | CD7: 6.6134 | CE7: 30.847 | CF7: 84.638 | CG7: 48.917 | CH7: 31.5295 | CI7: 55.0811 | CJ7: 28.18 | CK7: 40.577 | CL7: 4.915 | CM7: 42.901 | CN7: 21.1145 | CO7: 12.0745 | CP7: 18.228 | CQ7: 32.9395 | CR7: 18.5215 | CS7: 24.864 | CT7: 11.21 | CU7: =IFERROR(VLOOKUP(A7,'fat-01-24'!A:C,3,FALSE),"") -> 12.151 | CV7: =IFERROR(VLOOKUP(A7,'fat-02-24'!A:C,3,FALSE),"") -> 12.8885 | CW7: =IFERROR(VLOOKUP(A7,'fat-03-24'!A:C,3,FALSE),"") -> 115.093 | CX7: =IFERROR(VLOOKUP(A7,'fat-04-24'!A:C,3,FALSE),"") -> 31.7265 | CY7: =IFERROR(VLOOKUP(A7,'fat-05-24'!A:C,3,FALSE),"") -> 30.5397 | CZ7: =IFERROR(VLOOKUP(A7,'fat-06-24'!A:C,3,FALSE),"") -> 21.1145 | DA7: =IFERROR(VLOOKUP(A7,'fat-07-24'!A:C,3,FALSE),"") -> 3.082 | DB7: =IFERROR(VLOOKUP(A7,'fat-08-24'!A:D,3,FALSE),"") -> 12.9955 | DC7: =IFERROR(VLOOKUP(A7,'fat-09-24'!A:C,3,FALSE),"") -> 53.4525 | DD7: =IFERROR(VLOOKUP(A7,'fat-10-24'!A:C,3,FALSE),"") -> 59.488 | DE7: =IFERROR(VLOOKUP(A7,'fat-11-24'!A:C,3,FALSE),"") -> 19.922 | DF7: =IFERROR(VLOOKUP(A7,'fat-12-24'!A:D,3,FALSE),"") -> 63.9795 | DG7: =IFERROR(VLOOKUP(A7,'fat-01-25'!A:D,3,FALSE),"") -> 19.959 | DH7: =IFERROR(VLOOKUP(A7,'fat-02-25'!A:D,3,FALSE),"") -> 30.8349 | DI7: =IFERROR(VLOOKUP(A7,'fat-03-25'!A:C,3,FALSE),"") -> 27.5105 | DJ7: =IFERROR(VLOOKUP(A7,'fat-04-25'!A:C,3,FALSE),"") -> 44.7573 | DK7: =IFERROR(VLOOKUP(A7,'fat-02-25'!A:C,3,FALSE),"") -> 30.8349 | DL7: =IFERROR(VLOOKUP(A7,'fat-06-25'!A:C,3,FALSE),"") -> 13.1755 | DM7: =IFERROR(VLOOKUP(A7,'fat-05-25'!A:C,3,FALSE),"") -> 24.788 | DN7: =IFERROR(VLOOKUP(A7,'fat-08-25'!A:C,3,FALSE),"") -> 36.732 | DO7: =IFERROR(VLOOKUP(A7,'fat-09-25'!A:C,3,FALSE),"") -> 30.28 | DP7: =IFERROR(VLOOKUP(A7,'fat-10-25'!A:C,3,FALSE),"") -> 5.646 | DQ7: =IFERROR(VLOOKUP(A7,'fat-11-25'!A:D,3,FALSE),"") -> 28.9395 | DR7: =IFERROR(VLOOKUP(A7,'fat-12-25'!A:D,3,FALSE),"") -> 11.973 | DS7: =IFERROR(VLOOKUP(A7,'fat-01-26'!A:C,3,FALSE),"") -> 29.4945 | DT7: =IFERROR(VLOOKUP(A7,'fat-02-26'!A:C,3,FALSE),"") -> 50.971 | DU7: =IFERROR(VLOOKUP(A7,'fat-03-26'!A:C,3,FALSE),"") -> 108.809 | DV7: =IFERROR(VLOOKUP(A7,'fat-04-26'!A:C,3,FALSE),"") -> 30.4565 | DW7: =IFERROR(VLOOKUP(A7,'fat-05-26'!A:C,3,FALSE),"") -> 38.0235 | DX7: =SUM(DR7:DW7)/6 -> 44.954583 | DY7: =DX7/30*45 -> 67.431875 | EA7: =VLOOKUP(A7,Estoque!B:I,8,FALSE) -> 60.4503 | EB7: =VLOOKUP(A7,Estoque!B:N,13,FALSE) -> 0 | ED7: 50 | EE7: 50
A8: PRF10006 | B8: PERFIL U ENRIJ LQ 1,80 X 100 X 50 X 17 MM | C8: 7.43 | D8: 1.796 | E8: 6.247 | F8: 9 | G8: 0.1199 | H8: 6.848 | J8: 0.955 | K8: 9.39 | L8: 5.995 | N8: 4.125 | P8: 2.63 | Q8: 2.993 | R8: 0.055 | T8: 0.873 | U8: 2.865 | V8: 1.3023 | W8: 3.558 | X8: 0.951 | Y8: 0.27 | AA8: 2.824 | AC8: 2.41 | AD8: 1.466 | AE8: 2.04 | AF8: 4.275 | AG8: 1.254 | AI8: 1.325 | AJ8: 8.647 | AK8: 1.96 | AL8: 5.21 | AM8: 1.87 | AN8: 3.745 | AO8: 0.985 | AP8: 11.497 | AQ8: 5.453 | AS8: 4.809 | AT8: 8.575 | AU8: 3.38 | AV8: 7.812 | AW8: 6.355 | AX8: 1.895 | AY8: 2.931 | AZ8: 3.3 | BA8: 14.26 | BB8: 0.56 | BC8: 4.19 | BD8: 10.715 | BE8: 3.25 | BF8: 8.177 | BH8: 1.625 | BI8: 5.214 | BJ8: 10.2 | BK8: 12.95 | BL8: 8.089 | BM8: 14.47 | BN8: 0.885 | BO8: 5.995 | BP8: 8.73 | BQ8: 3.17 | BR8: 3.895 | BS8: 6.808 | BT8: 0.485 | BU8: 2.535 | BV8: 2.966 | BW8: 5.13 | BY8: 0.965 | BZ8: 6.356 | CA8: 7.18 | CB8: 0.68 | CC8: 2.035 | CD8: 14.706 | CE8: 10.095 | CF8: 4.614 | CG8: 3.347 | CH8: 7.63 | CI8: 2.546 | CJ8: 0.435 | CK8: 11.4612 | CL8: 7.898 | CM8: 7.218 | CN8: 5.31 | CO8: 1.01 | CP8: 3.579 | CQ8: 4.0856 | CR8: 1.494 | CS8: 22.5426 | CT8: 11.6838 | CU8: =IFERROR(VLOOKUP(A8,'fat-01-24'!A:C,3,FALSE),"") -> 2.54 | CV8: =IFERROR(VLOOKUP(A8,'fat-02-24'!A:C,3,FALSE),"") -> 1.6638 | CW8: =IFERROR(VLOOKUP(A8,'fat-03-24'!A:C,3,FALSE),"") -> 16.64 | CX8: =IFERROR(VLOOKUP(A8,'fat-04-24'!A:C,3,FALSE),"") -> 3.938 | CY8: =IFERROR(VLOOKUP(A8,'fat-05-24'!A:C,3,FALSE),"") -> 11.824 | CZ8: =IFERROR(VLOOKUP(A8,'fat-06-24'!A:C,3,FALSE),"") -> 5.31 | DA8: =IFERROR(VLOOKUP(A8,'fat-07-24'!A:C,3,FALSE),"") -> 17.858 | DB8: =IFERROR(VLOOKUP(A8,'fat-08-24'!A:D,3,FALSE),"") -> 10.729 | DC8: =IFERROR(VLOOKUP(A8,'fat-09-24'!A:C,3,FALSE),"") -> 12.607 | DD8: =IFERROR(VLOOKUP(A8,'fat-10-24'!A:C,3,FALSE),"") -> 7.693 | DE8: =IFERROR(VLOOKUP(A8,'fat-11-24'!A:C,3,FALSE),"") -> 33.1834 | DF8: =IFERROR(VLOOKUP(A8,'fat-12-24'!A:D,3,FALSE),"") -> 26.7494 | DG8: =IFERROR(VLOOKUP(A8,'fat-01-25'!A:D,3,FALSE),"") -> 7.4522 | DH8: =IFERROR(VLOOKUP(A8,'fat-02-25'!A:D,3,FALSE),"") -> 7.001 | DI8: =IFERROR(VLOOKUP(A8,'fat-03-25'!A:C,3,FALSE),"") -> 48.1626 | DJ8: =IFERROR(VLOOKUP(A8,'fat-04-25'!A:C,3,FALSE),"") -> 4.756 | DK8: =IFERROR(VLOOKUP(A8,'fat-02-25'!A:C,3,FALSE),"") -> 7.001 | DL8: =IFERROR(VLOOKUP(A8,'fat-06-25'!A:C,3,FALSE),"") -> 1.59 | DM8: =IFERROR(VLOOKUP(A8,'fat-05-25'!A:C,3,FALSE),"") -> 2.309 | DN8: =IFERROR(VLOOKUP(A8,'fat-08-25'!A:C,3,FALSE),"") -> 8.902 | DO8: =IFERROR(VLOOKUP(A8,'fat-09-25'!A:C,3,FALSE),"") -> 16.951 | DP8: =IFERROR(VLOOKUP(A8,'fat-10-25'!A:C,3,FALSE),"") -> 16.61 | DQ8: =IFERROR(VLOOKUP(A8,'fat-11-25'!A:D,3,FALSE),"") -> 1.021 | DR8: =IFERROR(VLOOKUP(A8,'fat-12-25'!A:D,3,FALSE),"") -> 17.238 | DS8: =IFERROR(VLOOKUP(A8,'fat-01-26'!A:C,3,FALSE),"") -> 7.553 | DT8: =IFERROR(VLOOKUP(A8,'fat-02-26'!A:C,3,FALSE),"") -> 11.298 | DU8: =IFERROR(VLOOKUP(A8,'fat-03-26'!A:C,3,FALSE),"") -> 14.8588 | DV8: =IFERROR(VLOOKUP(A8,'fat-04-26'!A:C,3,FALSE),"") -> 9.264 | DW8: =IFERROR(VLOOKUP(A8,'fat-05-26'!A:C,3,FALSE),"") -> 20.483 | DX8: =SUM(DR8:DW8)/6 -> 13.449133 | DY8: =DX8/30*45 -> 20.1737 | EA8: =VLOOKUP(A8,Estoque!B:I,8,FALSE) -> -1.9066 | EB8: =VLOOKUP(A8,Estoque!B:N,13,FALSE) -> 0 | EC8: 15
A9: PRF10007 | B9: PERFIL U ENRIJ LQ 1,80 X 127 X 50 X 17 MM | E9: 0.658 | G9: 1.31 | H9: 1.345 | I9: 0.71 | L9: 2.03 | M9: 2.725 | O9: 18.49 | P9: 1.388 | Q9: 2.04 | S9: 5.28 | T9: 10.773 | U9: 11.33 | V9: 6.255 | W9: 2.232 | X9: 1.346 | AA9: 3.9 | AB9: 2.94 | AE9: 2.88 | AG9: 2.02 | AH9: 2.155 | AI9: 1.315 | AJ9: 1.205 | AK9: 0.525 | AL9: 10.21 | AM9: -1.05 | AN9: 2.165 | AO9: 0.1 | AP9: 0.8 | AQ9: 21.74 | AS9: 0.318 | AT9: 12.724 | AU9: 6.855 | AV9: 5.7179 | AW9: 0.714 | AX9: 3.49 | AY9: 1.31 | AZ9: 5.295 | BA9: 1.315 | BB9: 0.51 | BC9: 6.195 | BD9: 3.662 | BE9: 3.475 | BF9: 10.528 | BG9: 0.315 | BJ9: 0.115 | BK9: 2.66 | BL9: 8.12 | BM9: 0.91 | BO9: 0.702 | BP9: 2.21 | BR9: 0.76 | BT9: 1.405 | BV9: 1.49 | BX9: 0.31 | BY9: 0.325 | BZ9: 1.585 | CA9: 0.189 | CB9: 3.01 | CD9: 2.4 | CF9: 20.45 | CH9: 2.155 | CI9: 1.302 | CJ9: 4.305 | CK9: 13.209 | CL9: 1.155 | CM9: 5.161 | CN9: 7.098 | CO9: 1.239 | CP9: 16.018 | CR9: 9.501 | CS9: 3.8 | CT9: 14.429 | CU9: =IFERROR(VLOOKUP(A9,'fat-01-24'!A:C,3,FALSE),"") -> 6.111 | CV9: =IFERROR(VLOOKUP(A9,'fat-02-24'!A:C,3,FALSE),"") -> 2.032 | CW9: =IFERROR(VLOOKUP(A9,'fat-03-24'!A:C,3,FALSE),"") -> 10.57 | CX9: =IFERROR(VLOOKUP(A9,'fat-04-24'!A:C,3,FALSE),"") -> 12.931 | CY9: =IFERROR(VLOOKUP(A9,'fat-05-24'!A:C,3,FALSE),"") -> 4.377 | CZ9: =IFERROR(VLOOKUP(A9,'fat-06-24'!A:C,3,FALSE),"") -> 7.098 | DA9: =IFERROR(VLOOKUP(A9,'fat-07-24'!A:C,3,FALSE),"") -> 6.316 | DB9: =IFERROR(VLOOKUP(A9,'fat-08-24'!A:D,3,FALSE),"") -> 9.496 | DC9: =IFERROR(VLOOKUP(A9,'fat-09-24'!A:C,3,FALSE),"") -> 1.946 | DD9: =IFERROR(VLOOKUP(A9,'fat-10-24'!A:C,3,FALSE),"") -> 8.918 | DE9: =IFERROR(VLOOKUP(A9,'fat-11-24'!A:C,3,FALSE),"") -> 21.709 | DF9: =IFERROR(VLOOKUP(A9,'fat-12-24'!A:D,3,FALSE),"") -> 13.959 | DG9: =IFERROR(VLOOKUP(A9,'fat-01-25'!A:D,3,FALSE),"") -> 3.432 | DH9: =IFERROR(VLOOKUP(A9,'fat-02-25'!A:D,3,FALSE),"") -> 12.486 | DI9: =IFERROR(VLOOKUP(A9,'fat-03-25'!A:C,3,FALSE),"") -> 9.78 | DJ9: =IFERROR(VLOOKUP(A9,'fat-04-25'!A:C,3,FALSE),"") -> 20.65 | DK9: =IFERROR(VLOOKUP(A9,'fat-02-25'!A:C,3,FALSE),"") -> 12.486 | DL9: =IFERROR(VLOOKUP(A9,'fat-06-25'!A:C,3,FALSE),"") -> 3.082 | DM9: =IFERROR(VLOOKUP(A9,'fat-05-25'!A:C,3,FALSE),"") -> 1.743 | DN9: =IFERROR(VLOOKUP(A9,'fat-08-25'!A:C,3,FALSE),"") -> 8.938 | DO9: =IFERROR(VLOOKUP(A9,'fat-09-25'!A:C,3,FALSE),"") -> 12.622 | DP9: =IFERROR(VLOOKUP(A9,'fat-10-25'!A:C,3,FALSE),"") -> 3.331 | DQ9: =IFERROR(VLOOKUP(A9,'fat-11-25'!A:D,3,FALSE),"") | DR9: =IFERROR(VLOOKUP(A9,'fat-12-25'!A:D,3,FALSE),"") | DS9: =IFERROR(VLOOKUP(A9,'fat-01-26'!A:C,3,FALSE),"") -> 6.884 | DT9: =IFERROR(VLOOKUP(A9,'fat-02-26'!A:C,3,FALSE),"") -> 6.513 | DU9: =IFERROR(VLOOKUP(A9,'fat-03-26'!A:C,3,FALSE),"") -> 10.717 | DV9: =IFERROR(VLOOKUP(A9,'fat-04-26'!A:C,3,FALSE),"") -> 3.918 | DW9: =IFERROR(VLOOKUP(A9,'fat-05-26'!A:C,3,FALSE),"") -> 4.845 | DX9: =SUM(DR9:DW9)/6 -> 5.4795 | DY9: =DX9/30*45 -> 8.21925 | EA9: =VLOOKUP(A9,Estoque!B:I,8,FALSE) -> 10.006 | EB9: =VLOOKUP(A9,Estoque!B:N,13,FALSE) -> 0 | EC9: 10
A10: PRF10008 | B10: PERFIL U ENRIJ LQ 1,80 X 150 X 60 X 20 MM | C10: 4.68 | D10: 0.735 | G10: 0.49 | H10: 12.145 | N10: 0.865 | P10: 1.7 | Q10: 2.23 | S10: 2.37 | T10: 0.222 | U10: 2.23 | W10: 0.32 | AC10: 0.85 | AD10: 0.298 | AG10: 0.551 | AH10: 0.4 | AJ10: 4.35 | AK10: 1 | AL10: 1.426 | AM10: 4.745 | AN10: 3.311 | AP10: 2.37 | AQ10: 0.505 | AR10: 1 | AT10: 3.598 | AW10: 1.871 | AZ10: 0.42 | BA10: 0.12 | BB10: 8.43 | BC10: 0.325 | BD10: 5.295 | BE10: 3.845 | BF10: 6.842 | BG10: 7.533 | BH10: 5.625 | BI10: 0.5 | BJ10: 0.3 | BK10: 0.855 | BL10: 1 | BM10: 8.436 | BN10: 1.48 | BO10: 7.695 | BP10: 0.315 | BQ10: 3.415 | BU10: 0.985 | BV10: 0.785 | BX10: 6.305 | BY10: 9.53 | BZ10: 4.135 | CA10: 3.89 | CB10: 3.53 | CC10: 1.195 | CD10: 0.25 | CF10: 3.325 | CG10: 0.25 | CH10: 3.6 | CI10: 3.4 | CL10: 0.175 | CM10: 5.025 | CN10: 0.05 | CP10: 2.275 | CR10: 1.741 | CS10: 6.97 | CT10: 3.208 | CU10: =IFERROR(VLOOKUP(A10,'fat-01-24'!A:C,3,FALSE),"") -> 2.263 | CV10: =IFERROR(VLOOKUP(A10,'fat-02-24'!A:C,3,FALSE),"") -> 0.8 | CW10: =IFERROR(VLOOKUP(A10,'fat-03-24'!A:C,3,FALSE),"") -> 1.125 | CX10: =IFERROR(VLOOKUP(A10,'fat-04-24'!A:C,3,FALSE),"") -> 4.525 | CY10: =IFERROR(VLOOKUP(A10,'fat-05-24'!A:C,3,FALSE),"") -> 0.175 | CZ10: =IFERROR(VLOOKUP(A10,'fat-06-24'!A:C,3,FALSE),"") -> 0.05 | DA10: =IFERROR(VLOOKUP(A10,'fat-07-24'!A:C,3,FALSE),"") -> 7.815 | DB10: =IFERROR(VLOOKUP(A10,'fat-08-24'!A:D,3,FALSE),"") -> 2.4 | DC10: =IFERROR(VLOOKUP(A10,'fat-09-24'!A:C,3,FALSE),"") -> 6.396 | DD10: =IFERROR(VLOOKUP(A10,'fat-10-24'!A:C,3,FALSE),"") -> 2.01 | DE10: =IFERROR(VLOOKUP(A10,'fat-11-24'!A:C,3,FALSE),"") -> 2.37 | DF10: =IFERROR(VLOOKUP(A10,'fat-12-24'!A:D,3,FALSE),"") -> 13.075 | DG10: =IFERROR(VLOOKUP(A10,'fat-01-25'!A:D,3,FALSE),"") -> 0.675 | DH10: =IFERROR(VLOOKUP(A10,'fat-02-25'!A:D,3,FALSE),"") -> 2.71 | DI10: =IFERROR(VLOOKUP(A10,'fat-03-25'!A:C,3,FALSE),"") -> 0.425 | DJ10: =IFERROR(VLOOKUP(A10,'fat-04-25'!A:C,3,FALSE),"") -> 0 | DK10: =IFERROR(VLOOKUP(A10,'fat-02-25'!A:C,3,FALSE),"") -> 2.71 | DL10: =IFERROR(VLOOKUP(A10,'fat-06-25'!A:C,3,FALSE),"") -> 0.625 | DM10: =IFERROR(VLOOKUP(A10,'fat-05-25'!A:C,3,FALSE),"") -> 2 | DN10: =IFERROR(VLOOKUP(A10,'fat-08-25'!A:C,3,FALSE),"") -> 0 | DO10: =IFERROR(VLOOKUP(A10,'fat-09-25'!A:C,3,FALSE),"") -> 2.501 | DP10: =IFERROR(VLOOKUP(A10,'fat-10-25'!A:C,3,FALSE),"") -> 0.425 | DQ10: =IFERROR(VLOOKUP(A10,'fat-11-25'!A:D,3,FALSE),"") -> 1.6 | DR10: =IFERROR(VLOOKUP(A10,'fat-12-25'!A:D,3,FALSE),"") -> 0 | DS10: =IFERROR(VLOOKUP(A10,'fat-01-26'!A:C,3,FALSE),"") -> 11.325 | DT10: =IFERROR(VLOOKUP(A10,'fat-02-26'!A:C,3,FALSE),"") -> 6.14 | DU10: =IFERROR(VLOOKUP(A10,'fat-03-26'!A:C,3,FALSE),"") -> 2.69 | DV10: =IFERROR(VLOOKUP(A10,'fat-04-26'!A:C,3,FALSE),"") -> 3.476 | DW10: =IFERROR(VLOOKUP(A10,'fat-05-26'!A:C,3,FALSE),"") -> 1.455 | DX10: =SUM(DR10:DW10)/6 -> 4.181 | DY10: =DX10/30*45 -> 6.2715 | EA10: =VLOOKUP(A10,Estoque!B:I,8,FALSE) -> 39.0392 | EB10: =VLOOKUP(A10,Estoque!B:N,13,FALSE) -> 0 | ED10: 10
A11: PRF10009 | B11: PERFIL U ENRIJ LQ 1,80 X 150 X 50 X 20 MM | AS11: 18.127 | AT11: 2.11 | AU11: 4.16 | AV11: 3.09 | AW11: 3.45 | AZ11: 3.755 | BB11: 0.505 | BC11: 11.428 | BD11: 3.14 | BE11: 4.12 | BF11: 2.595 | BG11: 10.875 | BH11: 5.68 | BK11: 5.45 | BL11: 2 | BN11: 1 | BO11: 7.305 | BP11: 0.5 | BT11: 4.356 | BU11: 3.03 | BV11: 0.965 | BX11: 2.03 | BY11: 0.45 | BZ11: 12.325 | CB11: 0.925 | CC11: 1.52 | CD11: 9.024 | CF11: 1.904 | CG11: 0.48 | CH11: 3.815 | CI11: 3.504 | CK11: 2 | CL11: 5.088 | CM11: 5.61 | CN11: 2 | CP11: 3.532 | CQ11: 5.82 | CR11: 8.363 | CS11: 9.492 | CT11: 3.851 | CU11: =IFERROR(VLOOKUP(A11,'fat-01-24'!A:C,3,FALSE),"") -> 7.587 | CV11: =IFERROR(VLOOKUP(A11,'fat-02-24'!A:C,3,FALSE),"") -> 3.843 | CW11: =IFERROR(VLOOKUP(A11,'fat-03-24'!A:C,3,FALSE),"") -> 14.417 | CX11: =IFERROR(VLOOKUP(A11,'fat-04-24'!A:C,3,FALSE),"") -> 1.104 | CY11: =IFERROR(VLOOKUP(A11,'fat-05-24'!A:C,3,FALSE),"") -> 8.788 | CZ11: =IFERROR(VLOOKUP(A11,'fat-06-24'!A:C,3,FALSE),"") -> 2 | DA11: =IFERROR(VLOOKUP(A11,'fat-07-24'!A:C,3,FALSE),"") -> 5.354 | DB11: =IFERROR(VLOOKUP(A11,'fat-08-24'!A:D,3,FALSE),"") -> 9.317 | DC11: =IFERROR(VLOOKUP(A11,'fat-09-24'!A:C,3,FALSE),"") -> 10.192 | DD11: =IFERROR(VLOOKUP(A11,'fat-10-24'!A:C,3,FALSE),"") -> 8.637 | DE11: =IFERROR(VLOOKUP(A11,'fat-11-24'!A:C,3,FALSE),"") -> 14.966 | DF11: =IFERROR(VLOOKUP(A11,'fat-12-24'!A:D,3,FALSE),"") -> 17.274 | DG11: =IFERROR(VLOOKUP(A11,'fat-01-25'!A:D,3,FALSE),"") -> 5.808 | DH11: =IFERROR(VLOOKUP(A11,'fat-02-25'!A:D,3,FALSE),"") -> 16.392 | DI11: =IFERROR(VLOOKUP(A11,'fat-03-25'!A:C,3,FALSE),"") -> 6.436 | DJ11: =IFERROR(VLOOKUP(A11,'fat-04-25'!A:C,3,FALSE),"") -> 11.081 | DK11: =IFERROR(VLOOKUP(A11,'fat-02-25'!A:C,3,FALSE),"") -> 16.392 | DL11: =IFERROR(VLOOKUP(A11,'fat-06-25'!A:C,3,FALSE),"") -> 6.779 | DM11: =IFERROR(VLOOKUP(A11,'fat-05-25'!A:C,3,FALSE),"") -> 6.916 | DN11: =IFERROR(VLOOKUP(A11,'fat-08-25'!A:C,3,FALSE),"") -> 8.871 | DO11: =IFERROR(VLOOKUP(A11,'fat-09-25'!A:C,3,FALSE),"") -> 7.994 | DP11: =IFERROR(VLOOKUP(A11,'fat-10-25'!A:C,3,FALSE),"") -> 0 | DQ11: =IFERROR(VLOOKUP(A11,'fat-11-25'!A:D,3,FALSE),"") -> 3.712 | DR11: =IFERROR(VLOOKUP(A11,'fat-12-25'!A:D,3,FALSE),"") -> 0.816 | DS11: =IFERROR(VLOOKUP(A11,'fat-01-26'!A:C,3,FALSE),"") -> 4.476 | DT11: =IFERROR(VLOOKUP(A11,'fat-02-26'!A:C,3,FALSE),"") -> 0.408 | DU11: =IFERROR(VLOOKUP(A11,'fat-03-26'!A:C,3,FALSE),"") -> 14.03 | DV11: =IFERROR(VLOOKUP(A11,'fat-04-26'!A:C,3,FALSE),"") -> 8.998 | DW11: =IFERROR(VLOOKUP(A11,'fat-05-26'!A:C,3,FALSE),"") -> 1.348 | DX11: =SUM(DR11:DW11)/6 -> 5.0126667 | DY11: =DX11/30*45 -> 7.519 | EA11: =VLOOKUP(A11,Estoque!B:I,8,FALSE) -> -5.1482 | EB11: =VLOOKUP(A11,Estoque!B:N,13,FALSE) -> 0 | ED11: 10
A12: PRF10010 | B12: PERFIL U ENRIJ LQ 2,00 X 50 X 25 X 10 MM | C12: 0.7027 | D12: 11.4746 | E12: 6.699 | F12: 4.08 | G12: 0.055 | H12: 7.533 | I12: 0.845 | J12: 0.04 | K12: 6.025 | L12: 19.335 | M12: 0.05 | N12: 4.766 | O12: 1.169 | P12: 8.82 | Q12: 14.515 | R12: 1.395 | S12: 0.128 | T12: 0.14 | U12: 9.2472 | V12: 3.3114 | W12: 0.406 | X12: 2.867 | Y12: -0.915 | Z12: 9.625 | AA12: 1.039 | AB12: 0.436 | AC12: 0.195 | AD12: 0.029 | AE12: 2.06 | AF12: 1.063 | AG12: 3.296 | AH12: 0.619 | AI12: 6.923 | AJ12: 1.7425 | AK12: 6.4842 | AL12: 0.3 | AM12: 3.59 | AN12: 2.668 | AO12: 3.492 | AP12: 1.676 | AQ12: 6.66 | AR12: 12.48 | AS12: 0.94 | AT12: 3.412 | AU12: 14.309 | AV12: 22.529 | AW12: 10.124 | AX12: 0.475 | AY12: 7.741 | AZ12: 12.2808 | BA12: 8.214 | BB12: 8.352 | BC12: 21.378 | BD12: 23.723 | BE12: 21.4078 | BF12: 29.2537 | BG12: 25.13 | BH12: 8.239 | BI12: 40.898 | BK12: 13.21 | BL12: 72.26 | BM12: 26.6368 | BN12: 10.973 | BO12: 5.395 | BP12: 1.133 | BQ12: 4.256 | BR12: 0.893 | BS12: 1.124 | BT12: 2.131 | BU12: 3.463 | BV12: 0.285 | BW12: 1.498 | BX12: 3.434 | BY12: 7.104 | BZ12: 0.902 | CA12: 1.7738 | CB12: 4.8138 | CC12: 3.354 | CD12: 4.6602 | CE12: 2.636 | CF12: 10.2596 | CG12: 6.7147 | CH12: 24.9175 | CI12: 6.7818 | CJ12: 6.2274 | CK12: 5.276 | CL12: 5.8338 | CM12: 4.9032 | CN12: 4.7609 | CO12: 2.1495 | CP12: 3.0998 | CQ12: 12.7444 | CR12: 5.977 | CS12: 2.9274 | CT12: 6.7803 | CU12: =IFERROR(VLOOKUP(A12,'fat-01-24'!A:C,3,FALSE),"") -> 7.4436 | CV12: =IFERROR(VLOOKUP(A12,'fat-02-24'!A:C,3,FALSE),"") -> 4.7399 | CW12: =IFERROR(VLOOKUP(A12,'fat-03-24'!A:C,3,FALSE),"") -> 3.227 | CX12: =IFERROR(VLOOKUP(A12,'fat-04-24'!A:C,3,FALSE),"") -> 8.62799 | CY12: =IFERROR(VLOOKUP(A12,'fat-05-24'!A:C,3,FALSE),"") -> 10.2173 | CZ12: =IFERROR(VLOOKUP(A12,'fat-06-24'!A:C,3,FALSE),"") -> 4.7609 | DA12: =IFERROR(VLOOKUP(A12,'fat-07-24'!A:C,3,FALSE),"") -> 4.9385 | DB12: =IFERROR(VLOOKUP(A12,'fat-08-24'!A:D,3,FALSE),"") -> 9.0419 | DC12: =IFERROR(VLOOKUP(A12,'fat-09-24'!A:C,3,FALSE),"") -> 8.3887 | DD12: =IFERROR(VLOOKUP(A12,'fat-10-24'!A:C,3,FALSE),"") -> 13.4037 | DE12: =IFERROR(VLOOKUP(A12,'fat-11-24'!A:C,3,FALSE),"") -> 7.3144 | DF12: =IFERROR(VLOOKUP(A12,'fat-12-24'!A:D,3,FALSE),"") -> 7.7526 | DG12: =IFERROR(VLOOKUP(A12,'fat-01-25'!A:D,3,FALSE),"") -> 1.5067 | DH12: =IFERROR(VLOOKUP(A12,'fat-02-25'!A:D,3,FALSE),"") -> 10.5232 | DI12: =IFERROR(VLOOKUP(A12,'fat-03-25'!A:C,3,FALSE),"") -> 0.097 | DJ12: =IFERROR(VLOOKUP(A12,'fat-04-25'!A:C,3,FALSE),"") -> 6.6845 | DK12: =IFERROR(VLOOKUP(A12,'fat-02-25'!A:C,3,FALSE),"") -> 10.5232 | DL12: =IFERROR(VLOOKUP(A12,'fat-06-25'!A:C,3,FALSE),"") -> 7.9242 | DM12: =IFERROR(VLOOKUP(A12,'fat-05-25'!A:C,3,FALSE),"") -> 5.5293 | DN12: =IFERROR(VLOOKUP(A12,'fat-08-25'!A:C,3,FALSE),"") -> 3.5106 | DO12: =IFERROR(VLOOKUP(A12,'fat-09-25'!A:C,3,FALSE),"") -> 9.7847 | DP12: =IFERROR(VLOOKUP(A12,'fat-10-25'!A:C,3,FALSE),"") -> 4.137 | DQ12: =IFERROR(VLOOKUP(A12,'fat-11-25'!A:D,3,FALSE),"") -> 4.5247 | DR12: =IFERROR(VLOOKUP(A12,'fat-12-25'!A:D,3,FALSE),"") -> 3.2557 | DS12: =IFERROR(VLOOKUP(A12,'fat-01-26'!A:C,3,FALSE),"") -> 3.0116 | DT12: =IFERROR(VLOOKUP(A12,'fat-02-26'!A:C,3,FALSE),"") -> 13.8035 | DU12: =IFERROR(VLOOKUP(A12,'fat-03-26'!A:C,3,FALSE),"") -> 8.7864 | DV12: =IFERROR(VLOOKUP(A12,'fat-04-26'!A:C,3,FALSE),"") -> 3.362 | DW12: =IFERROR(VLOOKUP(A12,'fat-05-26'!A:C,3,FALSE),"") -> 2.8026 | DX12: =SUM(DR12:DW12)/6 -> 5.8369667 | DY12: =DX12/30*45 -> 8.75545 | EA12: =VLOOKUP(A12,Estoque!B:I,8,FALSE) -> 1.6597 | EB12: =VLOOKUP(A12,Estoque!B:N,13,FALSE) -> 5 | EC12: 40
A13: PRF10020 | B13: PERFIL U ENRIJ LQ 2,00 X 75 X 40 X 15 MM | C13: 10.0395 | D13: 20.6838 | E13: 42.6004 | F13: 28.8644 | G13: 5.436 | H13: 8.17 | I13: 14.8488 | J13: 10.841 | K13: 33.5726 | L13: 9.7562 | M13: 6.216 | N13: 4.072 | O13: 8.021 | P13: 7.2999 | Q13: 12.041 | R13: 0.327 | S13: 10.244 | T13: 4.544 | U13: 13.569 | V13: 9.979 | W13: 4.863 | X13: 11.816 | Y13: 13.121 | Z13: 0.886 | AA13: 22.801 | AB13: 2.6871 | AC13: 4.307 | AD13: 2.326 | AE13: 4.568 | AF13: 5.925 | AG13: 4.744 | AH13: 11.288 | AI13: 21.335 | AJ13: 15.372 | AK13: 12.964 | AL13: 9.162 | AM13: 13.364 | AN13: 18.7309 | AO13: 20.365 | AP13: 5.723 | AQ13: 10.7747 | AR13: 21.538 | AS13: 12.763 | AT13: 30.014 | AU13: 60.81 | AV13: 37.453 | AW13: 27.648 | AX13: 27.221 | AY13: 27.441 | AZ13: 21.776 | BA13: 59.237 | BB13: 39.342 | BC13: 34.496 | BD13: 49.978 | BE13: 27.688 | BF13: 45.433 | BG13: 102.263 | BH13: 29.5354 | BI13: 38.405 | BJ13: 80.201 | BK13: 106.115 | BL13: 46.366 | BM13: 42.633 | BN13: 28.0923 | BO13: 63.0904 | BP13: 59.324 | BQ13: 31.201 | BR13: 32.2971 | BS13: 29.4369 | BT13: 17.4299 | BU13: 14.768 | BV13: 19.4507 | BW13: 88.0218 | BX13: 42.816 | BY13: 41.5403 | BZ13: 17.002 | CA13: 23.084 | CB13: 48.457 | CC13: 18.7015 | CD13: 30.6018 | CE13: 60.78 | CF13: 69.954 | CG13: 39.1526 | CH13: 79.8729 | CI13: 55.017401 | CJ13: 11.4612 | CK13: 18.2402 | CL13: 25.1202 | CM13: 13.6146 | CN13: 14.7674 | CO13: 12.9231 | CP13: 46.6387 | CQ13: 34.7757 | CR13: 23.0289 | CS13: 37.6207 | CT13: 23.9017 | CU13: =IFERROR(VLOOKUP(A13,'fat-01-24'!A:C,3,FALSE),"") -> 26.3324 | CV13: =IFERROR(VLOOKUP(A13,'fat-02-24'!A:C,3,FALSE),"") -> 19.9657 | CW13: =IFERROR(VLOOKUP(A13,'fat-03-24'!A:C,3,FALSE),"") -> 34.8512 | CX13: =IFERROR(VLOOKUP(A13,'fat-04-24'!A:C,3,FALSE),"") -> 14.3273 | CY13: =IFERROR(VLOOKUP(A13,'fat-05-24'!A:C,3,FALSE),"") -> 26.4497 | CZ13: =IFERROR(VLOOKUP(A13,'fat-06-24'!A:C,3,FALSE),"") -> 14.7674 | DA13: =IFERROR(VLOOKUP(A13,'fat-07-24'!A:C,3,FALSE),"") -> 17.3697 | DB13: =IFERROR(VLOOKUP(A13,'fat-08-24'!A:D,3,FALSE),"") -> 20.0927 | DC13: =IFERROR(VLOOKUP(A13,'fat-09-24'!A:C,3,FALSE),"") -> 52.4029 | DD13: =IFERROR(VLOOKUP(A13,'fat-10-24'!A:C,3,FALSE),"") -> 27.8608 | DE13: =IFERROR(VLOOKUP(A13,'fat-11-24'!A:C,3,FALSE),"") -> 17.8887 | DF13: =IFERROR(VLOOKUP(A13,'fat-12-24'!A:D,3,FALSE),"") -> 6.9305 | DG13: =IFERROR(VLOOKUP(A13,'fat-01-25'!A:D,3,FALSE),"") -> 41.2182 | DH13: =IFERROR(VLOOKUP(A13,'fat-02-25'!A:D,3,FALSE),"") -> 18.944 | DI13: =IFERROR(VLOOKUP(A13,'fat-03-25'!A:C,3,FALSE),"") -> 15.949 | DJ13: =IFERROR(VLOOKUP(A13,'fat-04-25'!A:C,3,FALSE),"") -> 0.2058 | DK13: =IFERROR(VLOOKUP(A13,'fat-02-25'!A:C,3,FALSE),"") -> 18.944 | DL13: =IFERROR(VLOOKUP(A13,'fat-06-25'!A:C,3,FALSE),"") -> 21.022 | DM13: =IFERROR(VLOOKUP(A13,'fat-05-25'!A:C,3,FALSE),"") -> 24.7971 | DN13: =IFERROR(VLOOKUP(A13,'fat-08-25'!A:C,3,FALSE),"") -> 49.2417 | DO13: =IFERROR(VLOOKUP(A13,'fat-09-25'!A:C,3,FALSE),"") -> 40.7301 | DP13: =IFERROR(VLOOKUP(A13,'fat-10-25'!A:C,3,FALSE),"") -> 27.8852 | DQ13: =IFERROR(VLOOKUP(A13,'fat-11-25'!A:D,3,FALSE),"") -> 5.9969 | DR13: =IFERROR(VLOOKUP(A13,'fat-12-25'!A:D,3,FALSE),"") -> 6.6341 | DS13: =IFERROR(VLOOKUP(A13,'fat-01-26'!A:C,3,FALSE),"") -> 35.1389 | DT13: =IFERROR(VLOOKUP(A13,'fat-02-26'!A:C,3,FALSE),"") -> 16.3042 | DU13: =IFERROR(VLOOKUP(A13,'fat-03-26'!A:C,3,FALSE),"") -> 36.305 | DV13: =IFERROR(VLOOKUP(A13,'fat-04-26'!A:C,3,FALSE),"") -> 32.1003 | DW13: =IFERROR(VLOOKUP(A13,'fat-05-26'!A:C,3,FALSE),"") -> 34.7198 | DX13: =SUM(DR13:DW13)/6 -> 26.86705 | DY13: =DX13/30*45 -> 40.300575 | DZ13: 12 | EA13: =VLOOKUP(A13,Estoque!B:I,8,FALSE) -> 18.3426 | EB13: =VLOOKUP(A13,Estoque!B:N,13,FALSE) -> 20 | EC13: 70 | ED13: 70 | EE13: 70
